Workbook

Sheet Dashboard
A1: Onakit 2026 Contribution Dashboard
A3: Total Collection: | B3: =SUM('Master Sheet'!N3:N152) -> 111100
A4: Total Pending Members: | B4: =COUNTIF('Master Sheet'!P3:P152,"Pending") -> 149
A5: Total Completed Members: | B5: =COUNTIF('Master Sheet'!P3:P152,"Completed") -> 1
A7: Area-wise Collection
A8: Area 1 (Meenu S) | B8: =SUMIF('Master Sheet'!C3:C152,"Area 1 (Meenu S)",'Master Sheet'!N3:N152) -> 15550
A9: Area 2 (Viswakala S) | B9: =SUMIF('Master Sheet'!C3:C152,"Area 2 (Viswakala S)",'Master Sheet'!N3:N152) -> 8600
A10: Area 3 (Saranya R) | B10: =SUMIF('Master Sheet'!C3:C152,"Area 3 (Saranya R)",'Master Sheet'!N3:N152) -> 17700
A11: Area 4 (Anitha R) | B11: =SUMIF('Master Sheet'!C3:C152,"Area 4 (Anitha R)",'Master Sheet'!N3:N152) -> 11000
A12: Area 5 (Renuka A) | B12: =SUMIF('Master Sheet'!C3:C152,"Area 5 (Renuka A)",'Master Sheet'!N3:N152) -> 7000
A13: Area 6 (Anitha P) | B13: =SUMIF('Master Sheet'!C3:C152,"Area 6 (Anitha P)",'Master Sheet'!N3:N152) -> 12600
A14: Area 7 (Anu R) | B14: =SUMIF('Master Sheet'!C3:C152,"Area 7 (Anu R)",'Master Sheet'!N3:N152) -> 38650

Sheet Master Sheet
A1: Onakit -2026
A2: Person ID | B2: Name | C2: Area | D2: Oct | E2: Nov | F2: Dec | G2: Jan | H2: Feb | I2: Mar | J2: Apr | K2: May | L2: Jun | M2: Jul | N2: Total Paid | O2: Balance | P2: Status
A3: P001 | B3: Bindhu Alesh, Varayannur | C3: Area 1 (Meenu S) | D3: 350 | G3: 500 | N3: =SUM(D3:M3) -> 850 | O3: =3500-N3 -> 2650 | P3: =IF(O3<=0,"Completed","Pending") -> Pending
A4: P002 | B4: Aswathy PS, Kumbanadu | C4: Area 1 (Meenu S) | G4: 1000 | N4: =SUM(D4:M4) -> 1000 | O4: =3500-N4 -> 2500 | P4: =IF(O4<=0,"Completed","Pending") -> Pending
A5: P003 | B5: Arya , Kunnam, Poovathur | C5: Area 1 (Meenu S) | N5: =SUM(D5:M5) -> 0 | O5: =3500-N5 -> 3500 | P5: =IF(O5<=0,"Completed","Pending") -> Pending
A6: P004 | B6: Saratha Sasikumar, Varayannur | C6: Area 1 (Meenu S) | D6: 500 | G6: 500 | N6: =SUM(D6:M6) -> 1000 | O6: =3500-N6 -> 2500 | P6: =IF(O6<=0,"Completed","Pending") -> Pending
A7: P005 | B7: Gokul , Poovathur | C7: Area 1 (Meenu S) | G7: 2000 | N7: =SUM(D7:M7) -> 2000 | O7: =3500-N7 -> 1500 | P7: =IF(O7<=0,"Completed","Pending") -> Pending
A8: P006 | B8: Latha , Vrayannur | C8: Area 1 (Meenu S) | D8: 250 | G8: 500 | J8: t | N8: =SUM(D8:M8) -> 750 | O8: =3500-N8 -> 2750 | P8: =IF(O8<=0,"Completed","Pending") -> Pending
A9: P007 | B9: Viswapriya , Varayannur | C9: Area 1 (Meenu S) | D9: 250 | N9: =SUM(D9:M9) -> 250 | O9: =3500-N9 -> 3250 | P9: =IF(O9<=0,"Completed","Pending") -> Pending
A10: P008 | B10: Ambili Varayannur | C10: Area 1 (Meenu S) | D10: 250 | G10: 500 | N10: =SUM(D10:M10) -> 750 | O10: =3500-N10 -> 2750 | P10: =IF(O10<=0,"Completed","Pending") -> Pending
A11: P009 | B11: Ambili Varayannur | C11: Area 1 (Meenu S) | D11: 250 | N11: =SUM(D11:M11) -> 250 | O11: =3500-N11 -> 3250 | P11: =IF(O11<=0,"Completed","Pending") -> Pending
A12: P010 | B12: Lakshmi Ajeesh , Poovathur | C12: Area 1 (Meenu S) | N12: =SUM(D12:M12) -> 0 | O12: =3500-N12 -> 3500 | P12: =IF(O12<=0,"Completed","Pending") -> Pending
A13: P011 | B13: Seema Manoj , Poovathur | C13: Area 1 (Meenu S) | N13: =SUM(D13:M13) -> 0 | O13: =3500-N13 -> 3500 | P13: =IF(O13<=0,"Completed","Pending") -> Pending
A14: P012 | B14: Seema Manoj , Poovathur | C14: Area 1 (Meenu S) | N14: =SUM(D14:M14) -> 0 | O14: =3500-N14 -> 3500 | P14: =IF(O14<=0,"Completed","Pending") -> Pending
A15: P013 | B15: Shyla Pradeep , Poovathur | C15: Area 1 (Meenu S) | N15: =SUM(D15:M15) -> 0 | O15: =3500-N15 -> 3500 | P15: =IF(O15<=0,"Completed","Pending") -> Pending
A16: P014 | B16: Sreeja , Poovathur | C16: Area 1 (Meenu S) | F16: 350 | N16: =SUM(D16:M16) -> 350 | O16: =3500-N16 -> 3150 | P16: =IF(O16<=0,"Completed","Pending") -> Pending
A17: P015 | B17: Ambika , Poovathur | C17: Area 1 (Meenu S) | N17: =SUM(D17:M17) -> 0 | O17: =3500-N17 -> 3500 | P17: =IF(O17<=0,"Completed","Pending") -> Pending
A18: P016 | B18: Usha , Poovathur | C18: Area 1 (Meenu S) | G18: 500 | N18: =SUM(D18:M18) -> 500 | O18: =3500-N18 -> 3000 | P18: =IF(O18<=0,"Completed","Pending") -> Pending
A19: P017 | B19: Latha Shaji , Poovathur | C19: Area 1 (Meenu S) | N19: =SUM(D19:M19) -> 0 | O19: =3500-N19 -> 3500 | P19: =IF(O19<=0,"Completed","Pending") -> Pending
A20: P018 | B20: Smitha ,Poovathur | C20: Area 1 (Meenu S) | D20: 1000 | N20: =SUM(D20:M20) -> 1000 | O20: =3500-N20 -> 2500 | P20: =IF(O20<=0,"Completed","Pending") -> Pending
A21: P019 | B21: Harish , Chengannur | C21: Area 1 (Meenu S) | G21: 1000 | N21: =SUM(D21:M21) -> 1000 | O21: =3500-N21 -> 2500 | P21: =IF(O21<=0,"Completed","Pending") -> Pending
A22: P020 | B22: Bhaskaran Nukathala | C22: Area 1 (Meenu S) | F22: 500 | N22: =SUM(D22:M22) -> 500 | O22: =3500-N22 -> 3000 | P22: =IF(O22<=0,"Completed","Pending") -> Pending
A23: P021 | B23: Sukumaran Nukathala | C23: Area 1 (Meenu S) | F23: 200 | G23: 100 | N23: =SUM(D23:M23) -> 300 | O23: =3500-N23 -> 3200 | P23: =IF(O23<=0,"Completed","Pending") -> Pending
A24: P022 | B24: Dhanalekshmi Thettupara | C24: Area 1 (Meenu S) | D24: 500 | F24: 300 | N24: =SUM(D24:M24) -> 800 | O24: =3500-N24 -> 2700 | P24: =IF(O24<=0,"Completed","Pending") -> Pending
A25: P023 | B25: Meenu ,Poovathur | C25: Area 1 (Meenu S) | N25: =SUM(D25:M25) -> 0 | O25: =3500-N25 -> 3500 | P25: =IF(O25<=0,"Completed","Pending") -> Pending
A26: P024 | B26: Remya Dinesh , Poovathur | C26: Area 1 (Meenu S) | N26: =SUM(D26:M26) -> 0 | O26: =3500-N26 -> 3500 | P26: =IF(O26<=0,"Completed","Pending") -> Pending
A27: P025 | B27: Geethu Mohan | C27: Area 1 (Meenu S) | N27: =SUM(D27:M27) -> 0 | O27: =3500-N27 -> 3500 | P27: =IF(O27<=0,"Completed","Pending") -> Pending
A28: P026 | B28: Sreeja Teacher , Kuttur | C28: Area 1 (Meenu S) | D28: 750 | N28: =SUM(D28:M28) -> 750 | O28: =3500-N28 -> 2750 | P28: =IF(O28<=0,"Completed","Pending") -> Pending
A29: P027 | B29: Sreeja Teacher , Kuttur | C29: Area 1 (Meenu S) | N29: =SUM(D29:M29) -> 0 | O29: =3500-N29 -> 3500 | P29: =IF(O29<=0,"Completed","Pending") -> Pending
A30: P028 | B30: Jaya , Chengannur | C30: Area 1 (Meenu S) | N30: =SUM(D30:M30) -> 0 | O30: =3500-N30 -> 3500 | P30: =IF(O30<=0,"Completed","Pending") -> Pending
A31: P029 | B31: SatheeshKumar , Pullad | C31: Area 1 (Meenu S) | D31: 500 | E31: 500 | F31: 500 | N31: =SUM(D31:M31) -> 1500 | O31: =3500-N31 -> 2000 | P31: =IF(O31<=0,"Completed","Pending") -> Pending
A32: P030 | B32: Subash , Nukathala | C32: Area 1 (Meenu S) | N32: =SUM(D32:M32) -> 0 | O32: =3500-N32 -> 3500 | P32: =IF(O32<=0,"Completed","Pending") -> Pending
A33: P031 | B33: Sreeja Varayannur | C33: Area 1 (Meenu S) | F33: 500 | G33: 1500 | N33: =SUM(D33:M33) -> 2000 | O33: =3500-N33 -> 1500 | P33: =IF(O33<=0,"Completed","Pending") -> Pending
A34: P032 | B34: Dinesh , Pullad | C34: Area 2 (Viswakala S) | D34: 500 | F34: 350 | G34: 500 | N34: =SUM(D34:M34) -> 1350 | O34: =3500-N34 -> 2150 | P34: =IF(O34<=0,"Completed","Pending") -> Pending
A35: P033 | B35: Revathy , Pullad | C35: Area 2 (Viswakala S) | N35: =SUM(D35:M35) -> 0 | O35: =3500-N35 -> 3500 | P35: =IF(O35<=0,"Completed","Pending") -> Pending
A36: P034 | B36: Maya Gopal , Pullad | C36: Area 2 (Viswakala S) | E36: 500 | G36: 500 | N36: =SUM(D36:M36) -> 1000 | O36: =3500-N36 -> 2500 | P36: =IF(O36<=0,"Completed","Pending") -> Pending
A37: P035 | B37: Bini Sunil , Pullad | C37: Area 2 (Viswakala S) | E37: 350 | F37: 350 | G37: 350 | N37: =SUM(D37:M37) -> 1050 | O37: =3500-N37 -> 2450 | P37: =IF(O37<=0,"Completed","Pending") -> Pending
A38: P036 | B38: Ganga Rajamohan | C38: Area 2 (Viswakala S) | D38: 350 | F38: 1000 | N38: =SUM(D38:M38) -> 1350 | O38: =3500-N38 -> 2150 | P38: =IF(O38<=0,"Completed","Pending") -> Pending
A39: P037 | B39: Sona , Vadakekavala | C39: Area 2 (Viswakala S) | E39: 700 | N39: =SUM(D39:M39) -> 700 | O39: =3500-N39 -> 2800 | P39: =IF(O39<=0,"Completed","Pending") -> Pending
A40: P038 | B40: Indira Vijayan , Pullad | C40: Area 2 (Viswakala S) | E40: 400 | G40: 300 | N40: =SUM(D40:M40) -> 700 | O40: =3500-N40 -> 2800 | P40: =IF(O40<=0,"Completed","Pending") -> Pending
...

Sheet Area 1 (Meenu S)
A1: Person ID | B1: Name | C1: Area | D1: Oct | E1: Nov | F1: Dec | G1: Jan | H1: Feb | I1: Mar | J1: Apr | K1: May | L1: Jun | M1: Jul | N1: Total Paid | O1: Balance | P1: Status
A2: =IF('Master Sheet'!C3="Area 1 (Meenu S)",'Master Sheet'!A3,"") -> P001 | B2: =IF('Master Sheet'!C3="Area 1 (Meenu S)",'Master Sheet'!B3,"") -> Bindhu Alesh, Varayannur | C2: Area 1 (Meenu S) | D2: =IF('Master Sheet'!C3="Area 1 (Meenu S)",'Master Sheet'!D3,"") -> 350 | E2: =IF('Master Sheet'!C3="Area 1 (Meenu S)",'Master Sheet'!E3,"") -> 0 | F2: =IF('Master Sheet'!C3="Area 1 (Meenu S)",'Master Sheet'!F3,"") -> 0 | G2: =IF('Master Sheet'!C3="Area 1 (Meenu S)",'Master Sheet'!G3,"") -> 500 | H2: =IF('Master Sheet'!C3="Area 1 (Meenu S)",'Master Sheet'!H3,"") -> 0 | I2: =IF('Master Sheet'!C3="Area 1 (Meenu S)",'Master Sheet'!I3,"") -> 0 | J2: =IF('Master Sheet'!C3="Area 1 (Meenu S)",'Master Sheet'!J3,"") -> 0 | K2: =IF('Master Sheet'!C3="Area 1 (Meenu S)",'Master Sheet'!K3,"") -> 0 | L2: =IF('Master Sheet'!C3="Area 1 (Meenu S)",'Master Sheet'!L3,"") -> 0 | M2: =IF('Master Sheet'!C3="Area 1 (Meenu S)",'Master Sheet'!M3,"") -> 0 | N2: =IF('Master Sheet'!C3="Area 1 (Meenu S)",'Master Sheet'!N3,"") -> 850 | O2: =IF('Master Sheet'!C3="Area 1 (Meenu S)",'Master Sheet'!O3,"") -> 2650 | P2: =IF('Master Sheet'!C3="Area 1 (Meenu S)",'Master Sheet'!P3,"") -> Pending
A3: =IF('Master Sheet'!C4="Area 1 (Meenu S)",'Master Sheet'!A4,"") -> P002 | B3: =IF('Master Sheet'!C4="Area 1 (Meenu S)",'Master Sheet'!B4,"") -> Aswathy PS, Kumbanadu | C3: Area 1 (Meenu S) | D3: =IF('Master Sheet'!C4="Area 1 (Meenu S)",'Master Sheet'!D4,"") -> 0 | E3: =IF('Master Sheet'!C4="Area 1 (Meenu S)",'Master Sheet'!E4,"") -> 0 | F3: =IF('Master Sheet'!C4="Area 1 (Meenu S)",'Master Sheet'!F4,"") -> 0 | G3: =IF('Master Sheet'!C4="Area 1 (Meenu S)",'Master Sheet'!G4,"") -> 1000 | H3: =IF('Master Sheet'!C4="Area 1 (Meenu S)",'Master Sheet'!H4,"") -> 0 | I3: =IF('Master Sheet'!C4="Area 1 (Meenu S)",'Master Sheet'!I4,"") -> 0 | J3: =IF('Master Sheet'!C4="Area 1 (Meenu S)",'Master Sheet'!J4,"") -> 0 | K3: =IF('Master Sheet'!C4="Area 1 (Meenu S)",'Master Sheet'!K4,"") -> 0 | L3: =IF('Master Sheet'!C4="Area 1 (Meenu S)",'Master Sheet'!L4,"") -> 0 | M3: =IF('Master Sheet'!C4="Area 1 (Meenu S)",'Master Sheet'!M4,"") -> 0 | N3: =IF('Master Sheet'!C4="Area 1 (Meenu S)",'Master Sheet'!N4,"") -> 1000 | O3: =IF('Master Sheet'!C4="Area 1 (Meenu S)",'Master Sheet'!O4,"") -> 2500 | P3: =IF('Master Sheet'!C4="Area 1 (Meenu S)",'Master Sheet'!P4,"") -> Pending
A4: =IF('Master Sheet'!C5="Area 1 (Meenu S)",'Master Sheet'!A5,"") -> P003 | B4: =IF('Master Sheet'!C5="Area 1 (Meenu S)",'Master Sheet'!B5,"") -> Arya , Kunnam, Poovathur | C4: Area 1 (Meenu S) | D4: =IF('Master Sheet'!C5="Area 1 (Meenu S)",'Master Sheet'!D5,"") -> 0 | E4: =IF('Master Sheet'!C5="Area 1 (Meenu S)",'Master Sheet'!E5,"") -> 0 | F4: =IF('Master Sheet'!C5="Area 1 (Meenu S)",'Master Sheet'!F5,"") -> 0 | G4: =IF('Master Sheet'!C5="Area 1 (Meenu S)",'Master Sheet'!G5,"") -> 0 | H4: =IF('Master Sheet'!C5="Area 1 (Meenu S)",'Master Sheet'!H5,"") -> 0 | I4: =IF('Master Sheet'!C5="Area 1 (Meenu S)",'Master Sheet'!I5,"") -> 0 | J4: =IF('Master Sheet'!C5="Area 1 (Meenu S)",'Master Sheet'!J5,"") -> 0 | K4: =IF('Master Sheet'!C5="Area 1 (Meenu S)",'Master Sheet'!K5,"") -> 0 | L4: =IF('Master Sheet'!C5="Area 1 (Meenu S)",'Master Sheet'!L5,"") -> 0 | M4: =IF('Master Sheet'!C5="Area 1 (Meenu S)",'Master Sheet'!M5,"") -> 0 | N4: =IF('Master Sheet'!C5="Area 1 (Meenu S)",'Master Sheet'!N5,"") -> 0 | O4: =IF('Master Sheet'!C5="Area 1 (Meenu S)",'Master Sheet'!O5,"") -> 3500 | P4: =IF('Master Sheet'!C5="Area 1 (Meenu S)",'Master Sheet'!P5,"") -> Pending
A5: =IF('Master Sheet'!C6="Area 1 (Meenu S)",'Master Sheet'!A6,"") -> P004 | B5: =IF('Master Sheet'!C6="Area 1 (Meenu S)",'Master Sheet'!B6,"") -> Saratha Sasikumar, Varayannur | C5: Area 1 (Meenu S) | D5: =IF('Master Sheet'!C6="Area 1 (Meenu S)",'Master Sheet'!D6,"") -> 500 | E5: =IF('Master Sheet'!C6="Area 1 (Meenu S)",'Master Sheet'!E6,"") -> 0 | F5: =IF('Master Sheet'!C6="Area 1 (Meenu S)",'Master Sheet'!F6,"") -> 0 | G5: =IF('Master Sheet'!C6="Area 1 (Meenu S)",'Master Sheet'!G6,"") -> 500 | H5: =IF('Master Sheet'!C6="Area 1 (Meenu S)",'Master Sheet'!H6,"") -> 0 | I5: =IF('Master Sheet'!C6="Area 1 (Meenu S)",'Master Sheet'!I6,"") -> 0 | J5: =IF('Master Sheet'!C6="Area 1 (Meenu S)",'Master Sheet'!J6,"") -> 0 | K5: =IF('Master Sheet'!C6="Area 1 (Meenu S)",'Master Sheet'!K6,"") -> 0 | L5: =IF('Master Sheet'!C6="Area 1 (Meenu S)",'Master Sheet'!L6,"") -> 0 | M5: =IF('Master Sheet'!C6="Area 1 (Meenu S)",'Master Sheet'!M6,"") -> 0 | N5: =IF('Master Sheet'!C6="Area 1 (Meenu S)",'Master Sheet'!N6,"") -> 1000 | O5: =IF('Master Sheet'!C6="Area 1 (Meenu S)",'Master Sheet'!O6,"") -> 2500 | P5: =IF('Master Sheet'!C6="Area 1 (Meenu S)",'Master Sheet'!P6,"") -> Pending
A6: =IF('Master Sheet'!C7="Area 1 (Meenu S)",'Master Sheet'!A7,"") -> P005 | B6: =IF('Master Sheet'!C7="Area 1 (Meenu S)",'Master Sheet'!B7,"") -> Gokul , Poovathur | C6: Area 1 (Meenu S) | D6: =IF('Master Sheet'!C7="Area 1 (Meenu S)",'Master Sheet'!D7,"") -> 0 | E6: =IF('Master Sheet'!C7="Area 1 (Meenu S)",'Master Sheet'!E7,"") -> 0 | F6: =IF('Master Sheet'!C7="Area 1 (Meenu S)",'Master Sheet'!F7,"") -> 0 | G6: =IF('Master Sheet'!C7="Area 1 (Meenu S)",'Master Sheet'!G7,"") -> 2000 | H6: =IF('Master Sheet'!C7="Area 1 (Meenu S)",'Master Sheet'!H7,"") -> 0 | I6: =IF('Master Sheet'!C7="Area 1 (Meenu S)",'Master Sheet'!I7,"") -> 0 | J6: =IF('Master Sheet'!C7="Area 1 (Meenu S)",'Master Sheet'!J7,"") -> 0 | K6: =IF('Master Sheet'!C7="Area 1 (Meenu S)",'Master Sheet'!K7,"") -> 0 | L6: =IF('Master Sheet'!C7="Area 1 (Meenu S)",'Master Sheet'!L7,"") -> 0 | M6: =IF('Master Sheet'!C7="Area 1 (Meenu S)",'Master Sheet'!M7,"") -> 0 | N6: =IF('Master Sheet'!C7="Area 1 (Meenu S)",'Master Sheet'!N7,"") -> 2000 | O6: =IF('Master Sheet'!C7="Area 1 (Meenu S)",'Master Sheet'!O7,"") -> 1500 | P6: =IF('Master Sheet'!C7="Area 1 (Meenu S)",'Master Sheet'!P7,"") -> Pending
A7: =IF('Master Sheet'!C8="Area 1 (Meenu S)",'Master Sheet'!A8,"") -> P006 | B7: =IF('Master Sheet'!C8="Area 1 (Meenu S)",'Master Sheet'!B8,"") -> Latha , Vrayannur | C7: Area 1 (Meenu S) | D7: =IF('Master Sheet'!C8="Area 1 (Meenu S)",'Master Sheet'!D8,"") -> 250 | E7: =IF('Master Sheet'!C8="Area 1 (Meenu S)",'Master Sheet'!E8,"") -> 0 | F7: =IF('Master Sheet'!C8="Area 1 (Meenu S)",'Master Sheet'!F8,"") -> 0 | G7: =IF('Master Sheet'!C8="Area 1 (Meenu S)",'Master Sheet'!G8,"") -> 500 | H7: =IF('Master Sheet'!C8="Area 1 (Meenu S)",'Master Sheet'!H8,"") -> 0 | I7: =IF('Master Sheet'!C8="Area 1 (Meenu S)",'Master Sheet'!I8,"") -> 0 | J7: =IF('Master Sheet'!C8="Area 1 (Meenu S)",'Master Sheet'!J8,"") -> t | K7: =IF('Master Sheet'!C8="Area 1 (Meenu S)",'Master Sheet'!K8,"") -> 0 | L7: =IF('Master Sheet'!C8="Area 1 (Meenu S)",'Master Sheet'!L8,"") -> 0 | M7: =IF('Master Sheet'!C8="Area 1 (Meenu S)",'Master Sheet'!M8,"") -> 0 | N7: =IF('Master Sheet'!C8="Area 1 (Meenu S)",'Master Sheet'!N8,"") -> 750 | O7: =IF('Master Sheet'!C8="Area 1 (Meenu S)",'Master Sheet'!O8,"") -> 2750 | P7: =IF('Master Sheet'!C8="Area 1 (Meenu S)",'Master Sheet'!P8,"") -> Pending
A8: =IF('Master Sheet'!C9="Area 1 (Meenu S)",'Master Sheet'!A9,"") -> P007 | B8: =IF('Master Sheet'!C9="Area 1 (Meenu S)",'Master Sheet'!B9,"") -> Viswapriya , Varayannur | C8: Area 1 (Meenu S) | D8: =IF('Master Sheet'!C9="Area 1 (Meenu S)",'Master Sheet'!D9,"") -> 250 | E8: =IF('Master Sheet'!C9="Area 1 (Meenu S)",'Master Sheet'!E9,"") -> 0 | F8: =IF('Master Sheet'!C9="Area 1 (Meenu S)",'Master Sheet'!F9,"") -> 0 | G8: =IF('Master Sheet'!C9="Area 1 (Meenu S)",'Master Sheet'!G9,"") -> 0 | H8: =IF('Master Sheet'!C9="Area 1 (Meenu S)",'Master Sheet'!H9,"") -> 0 | I8: =IF('Master Sheet'!C9="Area 1 (Meenu S)",'Master Sheet'!I9,"") -> 0 | J8: =IF('Master Sheet'!C9="Area 1 (Meenu S)",'Master Sheet'!J9,"") -> 0 | K8: =IF('Master Sheet'!C9="Area 1 (Meenu S)",'Master Sheet'!K9,"") -> 0 | L8: =IF('Master Sheet'!C9="Area 1 (Meenu S)",'Master Sheet'!L9,"") -> 0 | M8: =IF('Master Sheet'!C9="Area 1 (Meenu S)",'Master Sheet'!M9,"") -> 0 | N8: =IF('Master Sheet'!C9="Area 1 (Meenu S)",'Master Sheet'!N9,"") -> 250 | O8: =IF('Master Sheet'!C9="Area 1 (Meenu S)",'Master Sheet'!O9,"") -> 3250 | P8: =IF('Master Sheet'!C9="Area 1 (Meenu S)",'Master Sheet'!P9,"") -> Pending
A9: =IF('Master Sheet'!C10="Area 1 (Meenu S)",'Master Sheet'!A10,"") -> P008 | B9: =IF('Master Sheet'!C10="Area 1 (Meenu S)",'Master Sheet'!B10,"") -> Ambili Varayannur | C9: Area 1 (Meenu S) | D9: =IF('Master Sheet'!C10="Area 1 (Meenu S)",'Master Sheet'!D10,"") -> 250 | E9: =IF('Master Sheet'!C10="Area 1 (Meenu S)",'Master Sheet'!E10,"") -> 0 | F9: =IF('Master Sheet'!C10="Area 1 (Meenu S)",'Master Sheet'!F10,"") -> 0 | G9: =IF('Master Sheet'!C10="Area 1 (Meenu S)",'Master Sheet'!G10,"") -> 500 | H9: =IF('Master Sheet'!C10="Area 1 (Meenu S)",'Master Sheet'!H10,"") -> 0 | I9: =IF('Master Sheet'!C10="Area 1 (Meenu S)",'Master Sheet'!I10,"") -> 0 | J9: =IF('Master Sheet'!C10="Area 1 (Meenu S)",'Master Sheet'!J10,"") -> 0 | K9: =IF('Master Sheet'!C10="Area 1 (Meenu S)",'Master Sheet'!K10,"") -> 0 | L9: =IF('Master Sheet'!C10="Area 1 (Meenu S)",'Master Sheet'!L10,"") -> 0 | M9: =IF('Master Sheet'!C10="Area 1 (Meenu S)",'Master Sheet'!M10,"") -> 0 | N9: =IF('Master Sheet'!C10="Area 1 (Meenu S)",'Master Sheet'!N10,"") -> 750 | O9: =IF('Master Sheet'!C10="Area 1 (Meenu S)",'Master Sheet'!O10,"") -> 2750 | P9: =IF('Master Sheet'!C10="Area 1 (Meenu S)",'Master Sheet'!P10,"") -> Pending
A10: =IF('Master Sheet'!C11="Area 1 (Meenu S)",'Master Sheet'!A11,"") -> P009 | B10: =IF('Master Sheet'!C11="Area 1 (Meenu S)",'Master Sheet'!B11,"") -> Ambili Varayannur | C10: Area 1 (Meenu S) | D10: =IF('Master Sheet'!C11="Area 1 (Meenu S)",'Master Sheet'!D11,"") -> 250 | E10: =IF('Master Sheet'!C11="Area 1 (Meenu S)",'Master Sheet'!E11,"") -> 0 | F10: =IF('Master Sheet'!C11="Area 1 (Meenu S)",'Master Sheet'!F11,"") -> 0 | G10: =IF('Master Sheet'!C11="Area 1 (Meenu S)",'Master Sheet'!G11,"") -> 0 | H10: =IF('Master Sheet'!C11="Area 1 (Meenu S)",'Master Sheet'!H11,"") -> 0 | I10: =IF('Master Sheet'!C11="Area 1 (Meenu S)",'Master Sheet'!I11,"") -> 0 | J10: =IF('Master Sheet'!C11="Area 1 (Meenu S)",'Master Sheet'!J11,"") -> 0 | K10: =IF('Master Sheet'!C11="Area 1 (Meenu S)",'Master Sheet'!K11,"") -> 0 | L10: =IF('Master Sheet'!C11="Area 1 (Meenu S)",'Master Sheet'!L11,"") -> 0 | M10: =IF('Master Sheet'!C11="Area 1 (Meenu S)",'Master Sheet'!M11,"") -> 0 | N10: =IF('Master Sheet'!C11="Area 1 (Meenu S)",'Master Sheet'!N11,"") -> 250 | O10: =IF('Master Sheet'!C11="Area 1 (Meenu S)",'Master Sheet'!O11,"") -> 3250 | P10: =IF('Master Sheet'!C11="Area 1 (Meenu S)",'Master Sheet'!P11,"") -> Pending
A11: =IF('Master Sheet'!C12="Area 1 (Meenu S)",'Master Sheet'!A12,"") -> P010 | B11: =IF('Master Sheet'!C12="Area 1 (Meenu S)",'Master Sheet'!B12,"") -> Lakshmi Ajeesh , Poovathur | C11: Area 1 (Meenu S) | D11: =IF('Master Sheet'!C12="Area 1 (Meenu S)",'Master Sheet'!D12,"") -> 0 | E11: =IF('Master Sheet'!C12="Area 1 (Meenu S)",'Master Sheet'!E12,"") -> 0 | F11: =IF('Master Sheet'!C12="Area 1 (Meenu S)",'Master Sheet'!F12,"") -> 0 | G11: =IF('Master Sheet'!C12="Area 1 (Meenu S)",'Master Sheet'!G12,"") -> 0 | H11: =IF('Master Sheet'!C12="Area 1 (Meenu S)",'Master Sheet'!H12,"") -> 0 | I11: =IF('Master Sheet'!C12="Area 1 (Meenu S)",'Master Sheet'!I12,"") -> 0 | J11: =IF('Master Sheet'!C12="Area 1 (Meenu S)",'Master Sheet'!J12,"") -> 0 | K11: =IF('Master Sheet'!C12="Area 1 (Meenu S)",'Master Sheet'!K12,"") -> 0 | L11: =IF('Master Sheet'!C12="Area 1 (Meenu S)",'Master Sheet'!L12,"") -> 0 | M11: =IF('Master Sheet'!C12="Area 1 (Meenu S)",'Master Sheet'!M12,"") -> 0 | N11: =IF('Master Sheet'!C12="Area 1 (Meenu S)",'Master Sheet'!N12,"") -> 0 | O11: =IF('Master Sheet'!C12="Area 1 (Meenu S)",'Master Sheet'!O12,"") -> 3500 | P11: =IF('Master Sheet'!C12="Area 1 (Meenu S)",'Master Sheet'!P12,"") -> Pending
A12: =IF('Master Sheet'!C13="Area 1 (Meenu S)",'Master Sheet'!A13,"") -> P011 | B12: =IF('Master Sheet'!C13="Area 1 (Meenu S)",'Master Sheet'!B13,"") -> Seema Manoj , Poovathur | C12: Area 1 (Meenu S) | D12: =IF('Master Sheet'!C13="Area 1 (Meenu S)",'Master Sheet'!D13,"") -> 0 | E12: =IF('Master Sheet'!C13="Area 1 (Meenu S)",'Master Sheet'!E13,"") -> 0 | F12: =IF('Master Sheet'!C13="Area 1 (Meenu S)",'Master Sheet'!F13,"") -> 0 | G12: =IF('Master Sheet'!C13="Area 1 (Meenu S)",'Master Sheet'!G13,"") -> 0 | H12: =IF('Master Sheet'!C13="Area 1 (Meenu S)",'Master Sheet'!H13,"") -> 0 | I12: =IF('Master Sheet'!C13="Area 1 (Meenu S)",'Master Sheet'!I13,"") -> 0 | J12: =IF('Master Sheet'!C13="Area 1 (Meenu S)",'Master Sheet'!J13,"") -> 0 | K12: =IF('Master Sheet'!C13="Area 1 (Meenu S)",'Master Sheet'!K13,"") -> 0 | L12: =IF('Master Sheet'!C13="Area 1 (Meenu S)",'Master Sheet'!L13,"") -> 0 | M12: =IF('Master Sheet'!C13="Area 1 (Meenu S)",'Master Sheet'!M13,"") -> 0 | N12: =IF('Master Sheet'!C13="Area 1 (Meenu S)",'Master Sheet'!N13,"") -> 0 | O12: =IF('Master Sheet'!C13="Area 1 (Meenu S)",'Master Sheet'!O13,"") -> 3500 | P12: =IF('Master Sheet'!C13="Area 1 (Meenu S)",'Master Sheet'!P13,"") -> Pending
A13: =IF('Master Sheet'!C14="Area 1 (Meenu S)",'Master Sheet'!A14,"") -> P012 | B13: =IF('Master Sheet'!C14="Area 1 (Meenu S)",'Master Sheet'!B14,"") -> Seema Manoj , Poovathur | C13: Area 1 (Meenu S) | D13: =IF('Master Sheet'!C14="Area 1 (Meenu S)",'Master Sheet'!D14,"") -> 0 | E13: =IF('Master Sheet'!C14="Area 1 (Meenu S)",'Master Sheet'!E14,"") -> 0 | F13: =IF('Master Sheet'!C14="Area 1 (Meenu S)",'Master Sheet'!F14,"") -> 0 | G13: =IF('Master Sheet'!C14="Area 1 (Meenu S)",'Master Sheet'!G14,"") -> 0 | H13: =IF('Master Sheet'!C14="Area 1 (Meenu S)",'Master Sheet'!H14,"") -> 0 | I13: =IF('Master Sheet'!C14="Area 1 (Meenu S)",'Master Sheet'!I14,"") -> 0 | J13: =IF('Master Sheet'!C14="Area 1 (Meenu S)",'Master Sheet'!J14,"") -> 0 | K13: =IF('Master Sheet'!C14="Area 1 (Meenu S)",'Master Sheet'!K14,"") -> 0 | L13: =IF('Master Sheet'!C14="Area 1 (Meenu S)",'Master Sheet'!L14,"") -> 0 | M13: =IF('Master Sheet'!C14="Area 1 (Meenu S)",'Master Sheet'!M14,"") -> 0 | N13: =IF('Master Sheet'!C14="Area 1 (Meenu S)",'Master Sheet'!N14,"") -> 0 | O13: =IF('Master Sheet'!C14="Area 1 (Meenu S)",'Master Sheet'!O14,"") -> 3500 | P13: =IF('Master Sheet'!C14="Area 1 (Meenu S)",'Master Sheet'!P14,"") -> Pending
... A151: =IF('Master Sheet'!C152="Area 1 (Meenu S)",'Master Sheet'!A152,"") | B151: =IF('Master Sheet'!C152="Area 1 (Meenu S)",'Master Sheet'!B152,"") | C151: Area 1 (Meenu S) | D151: =IF('Master Sheet'!C152="Area 1 (Meenu S)",'Master Sheet'!D152,"") | E151: =IF('Master Sheet'!C152="Area 1 (Meenu S)",'Master Sheet'!E152,"") | F151: =IF('Master Sheet'!C152="Area 1 (Meenu S)",'Master Sheet'!F152,"") | G151: =IF('Master Sheet'!C152="Area 1 (Meenu S)",'Master Sheet'!G152,"") | H151: =IF('Master Sheet'!C152="Area 1 (Meenu S)",'Master Sheet'!H152,"") | I151: =IF('Master Sheet'!C152="Area 1 (Meenu S)",'Master Sheet'!I152,"") | J151: =IF('Master Sheet'!C152="Area 1 (Meenu S)",'Master Sheet'!J152,"") | K151: =IF('Master Sheet'!C152="Area 1 (Meenu S)",'Master Sheet'!K152,"") | L151: =IF('Master Sheet'!C152="Area 1 (Meenu S)",'Master Sheet'!L152,"") | M151: =IF('Master Sheet'!C152="Area 1 (Meenu S)",'Master Sheet'!M152,"") | N151: =IF('Master Sheet'!C152="Area 1 (Meenu S)",'Master Sheet'!N152,"") | O151: =IF('Master Sheet'!C152="Area 1 (Meenu S)",'Master Sheet'!O152,"") | P151: =IF('Master Sheet'!C152="Area 1 (Meenu S)",'Master Sheet'!P152,"")
D152: =SUBTOTAL(9,D2:D151) -> 4600 | E152: =SUBTOTAL(9,E2:E151) -> 500 | F152: =SUBTOTAL(9,F2:F151) -> 2350 | G152: =SUBTOTAL(9,G2:G151) -> 8100 | H152: =SUBTOTAL(9,H2:H151) -> 0 | I152: =SUBTOTAL(9,I2:I151) -> 0 | J152: =SUBTOTAL(9,J2:J151) -> 0 | K152: =SUBTOTAL(9,K2:K151) -> 0 | ... M152: =SUBTOTAL(9,M2:M151) -> 0 | N152: =D152+E152+F152+G152+H152+I152+J152+K152+L152+M152 -> 15550

Sheet Area 2 (Viswakala S)
A1: Person ID | B1: Name | C1: Area | D1: Oct | E1: Nov | F1: Dec | G1: Jan | H1: Feb | I1: Mar | J1: Apr | K1: May | L1: Jun | M1: Jul | N1: Total Paid | O1: Balance | P1: Status
A2: =IF('Master Sheet'!C3="Area 2 (Viswakala S)",'Master Sheet'!A3,"") | B2: =IF('Master Sheet'!C3="Area 2 (Viswakala S)",'Master Sheet'!B3,"") | C2: Area 2 (Viswakala S) | D2: =IF('Master Sheet'!C3="Area 2 (Viswakala S)",'Master Sheet'!D3,"") | E2: =IF('Master Sheet'!C3="Area 2 (Viswakala S)",'Master Sheet'!E3,"") | F2: =IF('Master Sheet'!C3="Area 2 (Viswakala S)",'Master Sheet'!F3,"") | G2: =IF('Master Sheet'!C3="Area 2 (Viswakala S)",'Master Sheet'!G3,"") | H2: =IF('Master Sheet'!C3="Area 2 (Viswakala S)",'Master Sheet'!H3,"") | I2: =IF('Master Sheet'!C3="Area 2 (Viswakala S)",'Master Sheet'!I3,"") | J2: =IF('Master Sheet'!C3="Area 2 (Viswakala S)",'Master Sheet'!J3,"") | K2: =IF('Master Sheet'!C3="Area 2 (Viswakala S)",'Master Sheet'!K3,"") | L2: =IF('Master Sheet'!C3="Area 2 (Viswakala S)",'Master Sheet'!L3,"") | M2: =IF('Master Sheet'!C3="Area 2 (Viswakala S)",'Master Sheet'!M3,"") | N2: =IF('Master Sheet'!C3="Area 2 (Viswakala S)",'Master Sheet'!N3,"") | O2: =IF('Master Sheet'!C3="Area 2 (Viswakala S)",'Master Sheet'!O3,"") | P2: =IF('Master Sheet'!C3="Area 2 (Viswakala S)",'Master Sheet'!P3,"")
A3: =IF('Master Sheet'!C4="Area 2 (Viswakala S)",'Master Sheet'!A4,"") | B3: =IF('Master Sheet'!C4="Area 2 (Viswakala S)",'Master Sheet'!B4,"") | C3: Area 2 (Viswakala S) | D3: =IF('Master Sheet'!C4="Area 2 (Viswakala S)",'Master Sheet'!D4,"") | E3: =IF('Master Sheet'!C4="Area 2 (Viswakala S)",'Master Sheet'!E4,"") | F3: =IF('Master Sheet'!C4="Area 2 (Viswakala S)",'Master Sheet'!F4,"") | G3: =IF('Master Sheet'!C4="Area 2 (Viswakala S)",'Master Sheet'!G4,"") | H3: =IF('Master Sheet'!C4="Area 2 (Viswakala S)",'Master Sheet'!H4,"") | I3: =IF('Master Sheet'!C4="Area 2 (Viswakala S)",'Master Sheet'!I4,"") | J3: =IF('Master Sheet'!C4="Area 2 (Viswakala S)",'Master Sheet'!J4,"") | K3: =IF('Master Sheet'!C4="Area 2 (Viswakala S)",'Master Sheet'!K4,"") | L3: =IF('Master Sheet'!C4="Area 2 (Viswakala S)",'Master Sheet'!L4,"") | M3: =IF('Master Sheet'!C4="Area 2 (Viswakala S)",'Master Sheet'!M4,"") | N3: =IF('Master Sheet'!C4="Area 2 (Viswakala S)",'Master Sheet'!N4,"") | O3: =IF('Master Sheet'!C4="Area 2 (Viswakala S)",'Master Sheet'!O4,"") | P3: =IF('Master Sheet'!C4="Area 2 (Viswakala S)",'Master Sheet'!P4,"")
A4: =IF('Master Sheet'!C5="Area 2 (Viswakala S)",'Master Sheet'!A5,"") | B4: =IF('Master Sheet'!C5="Area 2 (Viswakala S)",'Master Sheet'!B5,"") | C4: Area 2 (Viswakala S) | D4: =IF('Master Sheet'!C5="Area 2 (Viswakala S)",'Master Sheet'!D5,"") | E4: =IF('Master Sheet'!C5="Area 2 (Viswakala S)",'Master Sheet'!E5,"") | F4: =IF('Master Sheet'!C5="Area 2 (Viswakala S)",'Master Sheet'!F5,"") | G4: =IF('Master Sheet'!C5="Area 2 (Viswakala S)",'Master Sheet'!G5,"") | H4: =IF('Master Sheet'!C5="Area 2 (Viswakala S)",'Master Sheet'!H5,"") | I4: =IF('Master Sheet'!C5="Area 2 (Viswakala S)",'Master Sheet'!I5,"") | J4: =IF('Master Sheet'!C5="Area 2 (Viswakala S)",'Master Sheet'!J5,"") | K4: =IF('Master Sheet'!C5="Area 2 (Viswakala S)",'Master Sheet'!K5,"") | L4: =IF('Master Sheet'!C5="Area 2 (Viswakala S)",'Master Sheet'!L5,"") | M4: =IF('Master Sheet'!C5="Area 2 (Viswakala S)",'Master Sheet'!M5,"") | N4: =IF('Master Sheet'!C5="Area 2 (Viswakala S)",'Master Sheet'!N5,"") | O4: =IF('Master Sheet'!C5="Area 2 (Viswakala S)",'Master Sheet'!O5,"") | P4: =IF('Master Sheet'!C5="Area 2 (Viswakala S)",'Master Sheet'!P5,"")
A5: =IF('Master Sheet'!C6="Area 2 (Viswakala S)",'Master Sheet'!A6,"") | B5: =IF('Master Sheet'!C6="Area 2 (Viswakala S)",'Master Sheet'!B6,"") | C5: Area 2 (Viswakala S) | D5: =IF('Master Sheet'!C6="Area 2 (Viswakala S)",'Master Sheet'!D6,"") | E5: =IF('Master Sheet'!C6="Area 2 (Viswakala S)",'Master Sheet'!E6,"") | F5: =IF('Master Sheet'!C6="Area 2 (Viswakala S)",'Master Sheet'!F6,"") | G5: =IF('Master Sheet'!C6="Area 2 (Viswakala S)",'Master Sheet'!G6,"") | H5: =IF('Master Sheet'!C6="Area 2 (Viswakala S)",'Master Sheet'!H6,"") | I5: =IF('Master Sheet'!C6="Area 2 (Viswakala S)",'Master Sheet'!I6,"") | J5: =IF('Master Sheet'!C6="Area 2 (Viswakala S)",'Master Sheet'!J6,"") | K5: =IF('Master Sheet'!C6="Area 2 (Viswakala S)",'Master Sheet'!K6,"") | L5: =IF('Master Sheet'!C6="Area 2 (Viswakala S)",'Master Sheet'!L6,"") | M5: =IF('Master Sheet'!C6="Area 2 (Viswakala S)",'Master Sheet'!M6,"") | N5: =IF('Master Sheet'!C6="Area 2 (Viswakala S)",'Master Sheet'!N6,"") | O5: =IF('Master Sheet'!C6="Area 2 (Viswakala S)",'Master Sheet'!O6,"") | P5: =IF('Master Sheet'!C6="Area 2 (Viswakala S)",'Master Sheet'!P6,"")
A6: =IF('Master Sheet'!C7="Area 2 (Viswakala S)",'Master Sheet'!A7,"") | B6: =IF('Master Sheet'!C7="Area 2 (Viswakala S)",'Master Sheet'!B7,"") | C6: Area 2 (Viswakala S) | D6: =IF('Master Sheet'!C7="Area 2 (Viswakala S)",'Master Sheet'!D7,"") | E6: =IF('Master Sheet'!C7="Area 2 (Viswakala S)",'Master Sheet'!E7,"") | F6: =IF('Master Sheet'!C7="Area 2 (Viswakala S)",'Master Sheet'!F7,"") | G6: =IF('Master Sheet'!C7="Area 2 (Viswakala S)",'Master Sheet'!G7,"") | H6: =IF('Master Sheet'!C7="Area 2 (Viswakala S)",'Master Sheet'!H7,"") | I6: =IF('Master Sheet'!C7="Area 2 (Viswakala S)",'Master Sheet'!I7,"") | J6: =IF('Master Sheet'!C7="Area 2 (Viswakala S)",'Master Sheet'!J7,"") | K6: =IF('Master Sheet'!C7="Area 2 (Viswakala S)",'Master Sheet'!K7,"") | L6: =IF('Master Sheet'!C7="Area 2 (Viswakala S)",'Master Sheet'!L7,"") | M6: =IF('Master Sheet'!C7="Area 2 (Viswakala S)",'Master Sheet'!M7,"") | N6: =IF('Master Sheet'!C7="Area 2 (Viswakala S)",'Master Sheet'!N7,"") | O6: =IF('Master Sheet'!C7="Area 2 (Viswakala S)",'Master Sheet'!O7,"") | P6: =IF('Master Sheet'!C7="Area 2 (Viswakala S)",'Master Sheet'!P7,"")
A7: =IF('Master Sheet'!C8="Area 2 (Viswakala S)",'Master Sheet'!A8,"") | B7: =IF('Master Sheet'!C8="Area 2 (Viswakala S)",'Master Sheet'!B8,"") | C7: Area 2 (Viswakala S) | D7: =IF('Master Sheet'!C8="Area 2 (Viswakala S)",'Master Sheet'!D8,"") | E7: =IF('Master Sheet'!C8="Area 2 (Viswakala S)",'Master Sheet'!E8,"") | F7: =IF('Master Sheet'!C8="Area 2 (Viswakala S)",'Master Sheet'!F8,"") | G7: =IF('Master Sheet'!C8="Area 2 (Viswakala S)",'Master Sheet'!G8,"") | H7: =IF('Master Sheet'!C8="Area 2 (Viswakala S)",'Master Sheet'!H8,"") | I7: =IF('Master Sheet'!C8="Area 2 (Viswakala S)",'Master Sheet'!I8,"") | J7: =IF('Master Sheet'!C8="Area 2 (Viswakala S)",'Master Sheet'!J8,"") | K7: =IF('Master Sheet'!C8="Area 2 (Viswakala S)",'Master Sheet'!K8,"") | L7: =IF('Master Sheet'!C8="Area 2 (Viswakala S)",'Master Sheet'!L8,"") | M7: =IF('Master Sheet'!C8="Area 2 (Viswakala S)",'Master Sheet'!M8,"") | N7: =IF('Master Sheet'!C8="Area 2 (Viswakala S)",'Master Sheet'!N8,"") | O7: =IF('Master Sheet'!C8="Area 2 (Viswakala S)",'Master Sheet'!O8,"") | P7: =IF('Master Sheet'!C8="Area 2 (Viswakala S)",'Master Sheet'!P8,"")
A8: =IF('Master Sheet'!C9="Area 2 (Viswakala S)",'Master Sheet'!A9,"") | B8: =IF('Master Sheet'!C9="Area 2 (Viswakala S)",'Master Sheet'!B9,"") | C8: Area 2 (Viswakala S) | D8: =IF('Master Sheet'!C9="Area 2 (Viswakala S)",'Master Sheet'!D9,"") | E8: =IF('Master Sheet'!C9="Area 2 (Viswakala S)",'Master Sheet'!E9,"") | F8: =IF('Master Sheet'!C9="Area 2 (Viswakala S)",'Master Sheet'!F9,"") | G8: =IF('Master Sheet'!C9="Area 2 (Viswakala S)",'Master Sheet'!G9,"") | H8: =IF('Master Sheet'!C9="Area 2 (Viswakala S)",'Master Sheet'!H9,"") | I8: =IF('Master Sheet'!C9="Area 2 (Viswakala S)",'Master Sheet'!I9,"") | J8: =IF('Master Sheet'!C9="Area 2 (Viswakala S)",'Master Sheet'!J9,"") | K8: =IF('Master Sheet'!C9="Area 2 (Viswakala S)",'Master Sheet'!K9,"") | L8: =IF('Master Sheet'!C9="Area 2 (Viswakala S)",'Master Sheet'!L9,"") | M8: =IF('Master Sheet'!C9="Area 2 (Viswakala S)",'Master Sheet'!M9,"") | N8: =IF('Master Sheet'!C9="Area 2 (Viswakala S)",'Master Sheet'!N9,"") | O8: =IF('Master Sheet'!C9="Area 2 (Viswakala S)",'Master Sheet'!O9,"") | P8: =IF('Master Sheet'!C9="Area 2 (Viswakala S)",'Master Sheet'!P9,"")
A9: =IF('Master Sheet'!C10="Area 2 (Viswakala S)",'Master Sheet'!A10,"") | B9: =IF('Master Sheet'!C10="Area 2 (Viswakala S)",'Master Sheet'!B10,"") | C9: Area 2 (Viswakala S) | D9: =IF('Master Sheet'!C10="Area 2 (Viswakala S)",'Master Sheet'!D10,"") | E9: =IF('Master Sheet'!C10="Area 2 (Viswakala S)",'Master Sheet'!E10,"") | F9: =IF('Master Sheet'!C10="Area 2 (Viswakala S)",'Master Sheet'!F10,"") | G9: =IF('Master Sheet'!C10="Area 2 (Viswakala S)",'Master Sheet'!G10,"") | H9: =IF('Master Sheet'!C10="Area 2 (Viswakala S)",'Master Sheet'!H10,"") | I9: =IF('Master Sheet'!C10="Area 2 (Viswakala S)",'Master Sheet'!I10,"") | J9: =IF('Master Sheet'!C10="Area 2 (Viswakala S)",'Master Sheet'!J10,"") | K9: =IF('Master Sheet'!C10="Area 2 (Viswakala S)",'Master Sheet'!K10,"") | L9: =IF('Master Sheet'!C10="Area 2 (Viswakala S)",'Master Sheet'!L10,"") | M9: =IF('Master Sheet'!C10="Area 2 (Viswakala S)",'Master Sheet'!M10,"") | N9: =IF('Master Sheet'!C10="Area 2 (Viswakala S)",'Master Sheet'!N10,"") | O9: =IF('Master Sheet'!C10="Area 2 (Viswakala S)",'Master Sheet'!O10,"") | P9: =IF('Master Sheet'!C10="Area 2 (Viswakala S)",'Master Sheet'!P10,"")
A10: =IF('Master Sheet'!C11="Area 2 (Viswakala S)",'Master Sheet'!A11,"") | B10: =IF('Master Sheet'!C11="Area 2 (Viswakala S)",'Master Sheet'!B11,"") | C10: Area 2 (Viswakala S) | D10: =IF('Master Sheet'!C11="Area 2 (Viswakala S)",'Master Sheet'!D11,"") | E10: =IF('Master Sheet'!C11="Area 2 (Viswakala S)",'Master Sheet'!E11,"") | F10: =IF('Master Sheet'!C11="Area 2 (Viswakala S)",'Master Sheet'!F11,"") | G10: =IF('Master Sheet'!C11="Area 2 (Viswakala S)",'Master Sheet'!G11,"") | H10: =IF('Master Sheet'!C11="Area 2 (Viswakala S)",'Master Sheet'!H11,"") | I10: =IF('Master Sheet'!C11="Area 2 (Viswakala S)",'Master Sheet'!I11,"") | J10: =IF('Master Sheet'!C11="Area 2 (Viswakala S)",'Master Sheet'!J11,"") | K10: =IF('Master Sheet'!C11="Area 2 (Viswakala S)",'Master Sheet'!K11,"") | L10: =IF('Master Sheet'!C11="Area 2 (Viswakala S)",'Master Sheet'!L11,"") | M10: =IF('Master Sheet'!C11="Area 2 (Viswakala S)",'Master Sheet'!M11,"") | N10: =IF('Master Sheet'!C11="Area 2 (Viswakala S)",'Master Sheet'!N11,"") | O10: =IF('Master Sheet'!C11="Area 2 (Viswakala S)",'Master Sheet'!O11,"") | P10: =IF('Master Sheet'!C11="Area 2 (Viswakala S)",'Master Sheet'!P11,"")
A11: =IF('Master Sheet'!C12="Area 2 (Viswakala S)",'Master Sheet'!A12,"") | B11: =IF('Master Sheet'!C12="Area 2 (Viswakala S)",'Master Sheet'!B12,"") | C11: Area 2 (Viswakala S) | D11: =IF('Master Sheet'!C12="Area 2 (Viswakala S)",'Master Sheet'!D12,"") | E11: =IF('Master Sheet'!C12="Area 2 (Viswakala S)",'Master Sheet'!E12,"") | F11: =IF('Master Sheet'!C12="Area 2 (Viswakala S)",'Master Sheet'!F12,"") | G11: =IF('Master Sheet'!C12="Area 2 (Viswakala S)",'Master Sheet'!G12,"") | H11: =IF('Master Sheet'!C12="Area 2 (Viswakala S)",'Master Sheet'!H12,"") | I11: =IF('Master Sheet'!C12="Area 2 (Viswakala S)",'Master Sheet'!I12,"") | J11: =IF('Master Sheet'!C12="Area 2 (Viswakala S)",'Master Sheet'!J12,"") | K11: =IF('Master Sheet'!C12="Area 2 (Viswakala S)",'Master Sheet'!K12,"") | L11: =IF('Master Sheet'!C12="Area 2 (Viswakala S)",'Master Sheet'!L12,"") | M11: =IF('Master Sheet'!C12="Area 2 (Viswakala S)",'Master Sheet'!M12,"") | N11: =IF('Master Sheet'!C12="Area 2 (Viswakala S)",'Master Sheet'!N12,"") | O11: =IF('Master Sheet'!C12="Area 2 (Viswakala S)",'Master Sheet'!O12,"") | P11: =IF('Master Sheet'!C12="Area 2 (Viswakala S)",'Master Sheet'!P12,"")
A12: =IF('Master Sheet'!C13="Area 2 (Viswakala S)",'Master Sheet'!A13,"") | B12: =IF('Master Sheet'!C13="Area 2 (Viswakala S)",'Master Sheet'!B13,"") | C12: Area 2 (Viswakala S) | D12: =IF('Master Sheet'!C13="Area 2 (Viswakala S)",'Master Sheet'!D13,"") | E12: =IF('Master Sheet'!C13="Area 2 (Viswakala S)",'Master Sheet'!E13,"") | F12: =IF('Master Sheet'!C13="Area 2 (Viswakala S)",'Master Sheet'!F13,"") | G12: =IF('Master Sheet'!C13="Area 2 (Viswakala S)",'Master Sheet'!G13,"") | H12: =IF('Master Sheet'!C13="Area 2 (Viswakala S)",'Master Sheet'!H13,"") | I12: =IF('Master Sheet'!C13="Area 2 (Viswakala S)",'Master Sheet'!I13,"") | J12: =IF('Master Sheet'!C13="Area 2 (Viswakala S)",'Master Sheet'!J13,"") | K12: =IF('Master Sheet'!C13="Area 2 (Viswakala S)",'Master Sheet'!K13,"") | L12: =IF('Master Sheet'!C13="Area 2 (Viswakala S)",'Master Sheet'!L13,"") | M12: =IF('Master Sheet'!C13="Area 2 (Viswakala S)",'Master Sheet'!M13,"") | N12: =IF('Master Sheet'!C13="Area 2 (Viswakala S)",'Master Sheet'!N13,"") | O12: =IF('Master Sheet'!C13="Area 2 (Viswakala S)",'Master Sheet'!O13,"") | P12: =IF('Master Sheet'!C13="Area 2 (Viswakala S)",'Master Sheet'!P13,"")
A13: =IF('Master Sheet'!C14="Area 2 (Viswakala S)",'Master Sheet'!A14,"") | B13: =IF('Master Sheet'!C14="Area 2 (Viswakala S)",'Master Sheet'!B14,"") | C13: Area 2 (Viswakala S) | D13: =IF('Master Sheet'!C14="Area 2 (Viswakala S)",'Master Sheet'!D14,"") | E13: =IF('Master Sheet'!C14="Area 2 (Viswakala S)",'Master Sheet'!E14,"") | F13: =IF('Master Sheet'!C14="Area 2 (Viswakala S)",'Master Sheet'!F14,"") | G13: =IF('Master Sheet'!C14="Area 2 (Viswakala S)",'Master Sheet'!G14,"") | H13: =IF('Master Sheet'!C14="Area 2 (Viswakala S)",'Master Sheet'!H14,"") | I13: =IF('Master Sheet'!C14="Area 2 (Viswakala S)",'Master Sheet'!I14,"") | J13: =IF('Master Sheet'!C14="Area 2 (Viswakala S)",'Master Sheet'!J14,"") | K13: =IF('Master Sheet'!C14="Area 2 (Viswakala S)",'Master Sheet'!K14,"") | L13: =IF('Master Sheet'!C14="Area 2 (Viswakala S)",'Master Sheet'!L14,"") | M13: =IF('Master Sheet'!C14="Area 2 (Viswakala S)",'Master Sheet'!M14,"") | N13: =IF('Master Sheet'!C14="Area 2 (Viswakala S)",'Master Sheet'!N14,"") | O13: =IF('Master Sheet'!C14="Area 2 (Viswakala S)",'Master Sheet'!O14,"") | P13: =IF('Master Sheet'!C14="Area 2 (Viswakala S)",'Master Sheet'!P14,"")
... A151: =IF('Master Sheet'!C152="Area 2 (Viswakala S)",'Master Sheet'!A152,"") | B151: =IF('Master Sheet'!C152="Area 2 (Viswakala S)",'Master Sheet'!B152,"") | C151: Area 2 (Viswakala S) | D151: =IF('Master Sheet'!C152="Area 2 (Viswakala S)",'Master Sheet'!D152,"") | E151: =IF('Master Sheet'!C152="Area 2 (Viswakala S)",'Master Sheet'!E152,"") | F151: =IF('Master Sheet'!C152="Area 2 (Viswakala S)",'Master Sheet'!F152,"") | G151: =IF('Master Sheet'!C152="Area 2 (Viswakala S)",'Master Sheet'!G152,"") | H151: =IF('Master Sheet'!C152="Area 2 (Viswakala S)",'Master Sheet'!H152,"") | I151: =IF('Master Sheet'!C152="Area 2 (Viswakala S)",'Master Sheet'!I152,"") | J151: =IF('Master Sheet'!C152="Area 2 (Viswakala S)",'Master Sheet'!J152,"") | K151: =IF('Master Sheet'!C152="Area 2 (Viswakala S)",'Master Sheet'!K152,"") | L151: =IF('Master Sheet'!C152="Area 2 (Viswakala S)",'Master Sheet'!L152,"") | M151: =IF('Master Sheet'!C152="Area 2 (Viswakala S)",'Master Sheet'!M152,"") | N151: =IF('Master Sheet'!C152="Area 2 (Viswakala S)",'Master Sheet'!N152,"") | O151: =IF('Master Sheet'!C152="Area 2 (Viswakala S)",'Master Sheet'!O152,"") | P151: =IF('Master Sheet'!C152="Area 2 (Viswakala S)",'Master Sheet'!P152,"")
D152: =SUBTOTAL(9,D33:D151) -> 1200 | E152: =SUBTOTAL(9,E33:E151) -> 2300 | F152: =SUBTOTAL(9,F33:F151) -> 2400 | G152: =SUBTOTAL(9,G33:G151) -> 2700 | H152: =SUBTOTAL(9,H33:H151) -> 0 | I152: =SUBTOTAL(9,I33:I151) -> 0 | J152: =SUBTOTAL(9,J33:J151) -> 0 | K152: =SUBTOTAL(9,K33:K151) -> 0 | ... M152: =SUBTOTAL(9,M33:M151) -> 0 | N152: =D152+E152+F152+G152+H152+I152+J152+K152+L152+M152 -> 8600

Sheet Area 3 (Saranya R)
A1: Person ID | B1: Name | C1: Area | D1: Oct | E1: Nov | F1: Dec | G1: Jan | H1: Feb | I1: Mar | J1: Apr | K1: May | L1: Jun | M1: Jul | N1: Total Paid | O1: Balance | P1: Status
A2: =IF('Master Sheet'!C3="Area 3 (Saranya R)",'Master Sheet'!A3,"") | B2: =IF('Master Sheet'!C3="Area 3 (Saranya R)",'Master Sheet'!B3,"") | C2: Area 3 (Saranya R) | D2: =IF('Master Sheet'!C3="Area 3 (Saranya R)",'Master Sheet'!D3,"") | E2: =IF('Master Sheet'!C3="Area 3 (Saranya R)",'Master Sheet'!E3,"") | F2: =IF('Master Sheet'!C3="Area 3 (Saranya R)",'Master Sheet'!F3,"") | G2: =IF('Master Sheet'!C3="Area 3 (Saranya R)",'Master Sheet'!G3,"") | H2: =IF('Master Sheet'!C3="Area 3 (Saranya R)",'Master Sheet'!H3,"") | I2: =IF('Master Sheet'!C3="Area 3 (Saranya R)",'Master Sheet'!I3,"") | J2: =IF('Master Sheet'!C3="Area 3 (Saranya R)",'Master Sheet'!J3,"") | K2: =IF('Master Sheet'!C3="Area 3 (Saranya R)",'Master Sheet'!K3,"") | L2: =IF('Master Sheet'!C3="Area 3 (Saranya R)",'Master Sheet'!L3,"") | M2: =IF('Master Sheet'!C3="Area 3 (Saranya R)",'Master Sheet'!M3,"") | N2: =IF('Master Sheet'!C3="Area 3 (Saranya R)",'Master Sheet'!N3,"") | O2: =IF('Master Sheet'!C3="Area 3 (Saranya R)",'Master Sheet'!O3,"") | P2: =IF('Master Sheet'!C3="Area 3 (Saranya R)",'Master Sheet'!P3,"")
A3: =IF('Master Sheet'!C4="Area 3 (Saranya R)",'Master Sheet'!A4,"") | B3: =IF('Master Sheet'!C4="Area 3 (Saranya R)",'Master Sheet'!B4,"") | C3: Area 3 (Saranya R) | D3: =IF('Master Sheet'!C4="Area 3 (Saranya R)",'Master Sheet'!D4,"") | E3: =IF('Master Sheet'!C4="Area 3 (Saranya R)",'Master Sheet'!E4,"") | F3: =IF('Master Sheet'!C4="Area 3 (Saranya R)",'Master Sheet'!F4,"") | G3: =IF('Master Sheet'!C4="Area 3 (Saranya R)",'Master Sheet'!G4,"") | H3: =IF('Master Sheet'!C4="Area 3 (Saranya R)",'Master Sheet'!H4,"") | I3: =IF('Master Sheet'!C4="Area 3 (Saranya R)",'Master Sheet'!I4,"") | J3: =IF('Master Sheet'!C4="Area 3 (Saranya R)",'Master Sheet'!J4,"") | K3: =IF('Master Sheet'!C4="Area 3 (Saranya R)",'Master Sheet'!K4,"") | L3: =IF('Master Sheet'!C4="Area 3 (Saranya R)",'Master Sheet'!L4,"") | M3: =IF('Master Sheet'!C4="Area 3 (Saranya R)",'Master Sheet'!M4,"") | N3: =IF('Master Sheet'!C4="Area 3 (Saranya R)",'Master Sheet'!N4,"") | O3: =IF('Master Sheet'!C4="Area 3 (Saranya R)",'Master Sheet'!O4,"") | P3: =IF('Master Sheet'!C4="Area 3 (Saranya R)",'Master Sheet'!P4,"")
A4: =IF('Master Sheet'!C5="Area 3 (Saranya R)",'Master Sheet'!A5,"") | B4: =IF('Master Sheet'!C5="Area 3 (Saranya R)",'Master Sheet'!B5,"") | C4: Area 3 (Saranya R) | D4: =IF('Master Sheet'!C5="Area 3 (Saranya R)",'Master Sheet'!D5,"") | E4: =IF('Master Sheet'!C5="Area 3 (Saranya R)",'Master Sheet'!E5,"") | F4: =IF('Master Sheet'!C5="Area 3 (Saranya R)",'Master Sheet'!F5,"") | G4: =IF('Master Sheet'!C5="Area 3 (Saranya R)",'Master Sheet'!G5,"") | H4: =IF('Master Sheet'!C5="Area 3 (Saranya R)",'Master Sheet'!H5,"") | I4: =IF('Master Sheet'!C5="Area 3 (Saranya R)",'Master Sheet'!I5,"") | J4: =IF('Master Sheet'!C5="Area 3 (Saranya R)",'Master Sheet'!J5,"") | K4: =IF('Master Sheet'!C5="Area 3 (Saranya R)",'Master Sheet'!K5,"") | L4: =IF('Master Sheet'!C5="Area 3 (Saranya R)",'Master Sheet'!L5,"") | M4: =IF('Master Sheet'!C5="Area 3 (Saranya R)",'Master Sheet'!M5,"") | N4: =IF('Master Sheet'!C5="Area 3 (Saranya R)",'Master Sheet'!N5,"") | O4: =IF('Master Sheet'!C5="Area 3 (Saranya R)",'Master Sheet'!O5,"") | P4: =IF('Master Sheet'!C5="Area 3 (Saranya R)",'Master Sheet'!P5,"")
A5: =IF('Master Sheet'!C6="Area 3 (Saranya R)",'Master Sheet'!A6,"") | B5: =IF('Master Sheet'!C6="Area 3 (Saranya R)",'Master Sheet'!B6,"") | C5: Area 3 (Saranya R) | D5: =IF('Master Sheet'!C6="Area 3 (Saranya R)",'Master Sheet'!D6,"") | E5: =IF('Master Sheet'!C6="Area 3 (Saranya R)",'Master Sheet'!E6,"") | F5: =IF('Master Sheet'!C6="Area 3 (Saranya R)",'Master Sheet'!F6,"") | G5: =IF('Master Sheet'!C6="Area 3 (Saranya R)",'Master Sheet'!G6,"") | H5: =IF('Master Sheet'!C6="Area 3 (Saranya R)",'Master Sheet'!H6,"") | I5: =IF('Master Sheet'!C6="Area 3 (Saranya R)",'Master Sheet'!I6,"") | J5: =IF('Master Sheet'!C6="Area 3 (Saranya R)",'Master Sheet'!J6,"") | K5: =IF('Master Sheet'!C6="Area 3 (Saranya R)",'Master Sheet'!K6,"") | L5: =IF('Master Sheet'!C6="Area 3 (Saranya R)",'Master Sheet'!L6,"") | M5: =IF('Master Sheet'!C6="Area 3 (Saranya R)",'Master Sheet'!M6,"") | N5: =IF('Master Sheet'!C6="Area 3 (Saranya R)",'Master Sheet'!N6,"") | O5: =IF('Master Sheet'!C6="Area 3 (Saranya R)",'Master Sheet'!O6,"") | P5: =IF('Master Sheet'!C6="Area 3 (Saranya R)",'Master Sheet'!P6,"")
A6: =IF('Master Sheet'!C7="Area 3 (Saranya R)",'Master Sheet'!A7,"") | B6: =IF('Master Sheet'!C7="Area 3 (Saranya R)",'Master Sheet'!B7,"") | C6: Area 3 (Saranya R) | D6: =IF('Master Sheet'!C7="Area 3 (Saranya R)",'Master Sheet'!D7,"") | E6: =IF('Master Sheet'!C7="Area 3 (Saranya R)",'Master Sheet'!E7,"") | F6: =IF('Master Sheet'!C7="Area 3 (Saranya R)",'Master Sheet'!F7,"") | G6: =IF('Master Sheet'!C7="Area 3 (Saranya R)",'Master Sheet'!G7,"") | H6: =IF('Master Sheet'!C7="Area 3 (Saranya R)",'Master Sheet'!H7,"") | I6: =IF('Master Sheet'!C7="Area 3 (Saranya R)",'Master Sheet'!I7,"") | J6: =IF('Master Sheet'!C7="Area 3 (Saranya R)",'Master Sheet'!J7,"") | K6: =IF('Master Sheet'!C7="Area 3 (Saranya R)",'Master Sheet'!K7,"") | L6: =IF('Master Sheet'!C7="Area 3 (Saranya R)",'Master Sheet'!L7,"") | M6: =IF('Master Sheet'!C7="Area 3 (Saranya R)",'Master Sheet'!M7,"") | N6: =IF('Master Sheet'!C7="Area 3 (Saranya R)",'Master Sheet'!N7,"") | O6: =IF('Master Sheet'!C7="Area 3 (Saranya R)",'Master Sheet'!O7,"") | P6: =IF('Master Sheet'!C7="Area 3 (Saranya R)",'Master Sheet'!P7,"")
A7: =IF('Master Sheet'!C8="Area 3 (Saranya R)",'Master Sheet'!A8,"") | B7: =IF('Master Sheet'!C8="Area 3 (Saranya R)",'Master Sheet'!B8,"") | C7: Area 3 (Saranya R) | D7: =IF('Master Sheet'!C8="Area 3 (Saranya R)",'Master Sheet'!D8,"") | E7: =IF('Master Sheet'!C8="Area 3 (Saranya R)",'Master Sheet'!E8,"") | F7: =IF('Master Sheet'!C8="Area 3 (Saranya R)",'Master Sheet'!F8,"") | G7: =IF('Master Sheet'!C8="Area 3 (Saranya R)",'Master Sheet'!G8,"") | H7: =IF('Master Sheet'!C8="Area 3 (Saranya R)",'Master Sheet'!H8,"") | I7: =IF('Master Sheet'!C8="Area 3 (Saranya R)",'Master Sheet'!I8,"") | J7: =IF('Master Sheet'!C8="Area 3 (Saranya R)",'Master Sheet'!J8,"") | K7: =IF('Master Sheet'!C8="Area 3 (Saranya R)",'Master Sheet'!K8,"") | L7: =IF('Master Sheet'!C8="Area 3 (Saranya R)",'Master Sheet'!L8,"") | M7: =IF('Master Sheet'!C8="Area 3 (Saranya R)",'Master Sheet'!M8,"") | N7: =IF('Master Sheet'!C8="Area 3 (Saranya R)",'Master Sheet'!N8,"") | O7: =IF('Master Sheet'!C8="Area 3 (Saranya R)",'Master Sheet'!O8,"") | P7: =IF('Master Sheet'!C8="Area 3 (Saranya R)",'Master Sheet'!P8,"")
A8: =IF('Master Sheet'!C9="Area 3 (Saranya R)",'Master Sheet'!A9,"") | B8: =IF('Master Sheet'!C9="Area 3 (Saranya R)",'Master Sheet'!B9,"") | C8: Area 3 (Saranya R) | D8: =IF('Master Sheet'!C9="Area 3 (Saranya R)",'Master Sheet'!D9,"") | E8: =IF('Master Sheet'!C9="Area 3 (Saranya R)",'Master Sheet'!E9,"") | F8: =IF('Master Sheet'!C9="Area 3 (Saranya R)",'Master Sheet'!F9,"") | G8: =IF('Master Sheet'!C9="Area 3 (Saranya R)",'Master Sheet'!G9,"") | H8: =IF('Master Sheet'!C9="Area 3 (Saranya R)",'Master Sheet'!H9,"") | I8: =IF('Master Sheet'!C9="Area 3 (Saranya R)",'Master Sheet'!I9,"") | J8: =IF('Master Sheet'!C9="Area 3 (Saranya R)",'Master Sheet'!J9,"") | K8: =IF('Master Sheet'!C9="Area 3 (Saranya R)",'Master Sheet'!K9,"") | L8: =IF('Master Sheet'!C9="Area 3 (Saranya R)",'Master Sheet'!L9,"") | M8: =IF('Master Sheet'!C9="Area 3 (Saranya R)",'Master Sheet'!M9,"") | N8: =IF('Master Sheet'!C9="Area 3 (Saranya R)",'Master Sheet'!N9,"") | O8: =IF('Master Sheet'!C9="Area 3 (Saranya R)",'Master Sheet'!O9,"") | P8: =IF('Master Sheet'!C9="Area 3 (Saranya R)",'Master Sheet'!P9,"")
A9: =IF('Master Sheet'!C10="Area 3 (Saranya R)",'Master Sheet'!A10,"") | B9: =IF('Master Sheet'!C10="Area 3 (Saranya R)",'Master Sheet'!B10,"") | C9: Area 3 (Saranya R) | D9: =IF('Master Sheet'!C10="Area 3 (Saranya R)",'Master Sheet'!D10,"") | E9: =IF('Master Sheet'!C10="Area 3 (Saranya R)",'Master Sheet'!E10,"") | F9: =IF('Master Sheet'!C10="Area 3 (Saranya R)",'Master Sheet'!F10,"") | G9: =IF('Master Sheet'!C10="Area 3 (Saranya R)",'Master Sheet'!G10,"") | H9: =IF('Master Sheet'!C10="Area 3 (Saranya R)",'Master Sheet'!H10,"") | I9: =IF('Master Sheet'!C10="Area 3 (Saranya R)",'Master Sheet'!I10,"") | J9: =IF('Master Sheet'!C10="Area 3 (Saranya R)",'Master Sheet'!J10,"") | K9: =IF('Master Sheet'!C10="Area 3 (Saranya R)",'Master Sheet'!K10,"") | L9: =IF('Master Sheet'!C10="Area 3 (Saranya R)",'Master Sheet'!L10,"") | M9: =IF('Master Sheet'!C10="Area 3 (Saranya R)",'Master Sheet'!M10,"") | N9: =IF('Master Sheet'!C10="Area 3 (Saranya R)",'Master Sheet'!N10,"") | O9: =IF('Master Sheet'!C10="Area 3 (Saranya R)",'Master Sheet'!O10,"") | P9: =IF('Master Sheet'!C10="Area 3 (Saranya R)",'Master Sheet'!P10,"")
A10: =IF('Master Sheet'!C11="Area 3 (Saranya R)",'Master Sheet'!A11,"") | B10: =IF('Master Sheet'!C11="Area 3 (Saranya R)",'Master Sheet'!B11,"") | C10: Area 3 (Saranya R) | D10: =IF('Master Sheet'!C11="Area 3 (Saranya R)",'Master Sheet'!D11,"") | E10: =IF('Master Sheet'!C11="Area 3 (Saranya R)",'Master Sheet'!E11,"") | F10: =IF('Master Sheet'!C11="Area 3 (Saranya R)",'Master Sheet'!F11,"") | G10: =IF('Master Sheet'!C11="Area 3 (Saranya R)",'Master Sheet'!G11,"") | H10: =IF('Master Sheet'!C11="Area 3 (Saranya R)",'Master Sheet'!H11,"") | I10: =IF('Master Sheet'!C11="Area 3 (Saranya R)",'Master Sheet'!I11,"") | J10: =IF('Master Sheet'!C11="Area 3 (Saranya R)",'Master Sheet'!J11,"") | K10: =IF('Master Sheet'!C11="Area 3 (Saranya R)",'Master Sheet'!K11,"") | L10: =IF('Master Sheet'!C11="Area 3 (Saranya R)",'Master Sheet'!L11,"") | M10: =IF('Master Sheet'!C11="Area 3 (Saranya R)",'Master Sheet'!M11,"") | N10: =IF('Master Sheet'!C11="Area 3 (Saranya R)",'Master Sheet'!N11,"") | O10: =IF('Master Sheet'!C11="Area 3 (Saranya R)",'Master Sheet'!O11,"") | P10: =IF('Master Sheet'!C11="Area 3 (Saranya R)",'Master Sheet'!P11,"")
A11: =IF('Master Sheet'!C12="Area 3 (Saranya R)",'Master Sheet'!A12,"") | B11: =IF('Master Sheet'!C12="Area 3 (Saranya R)",'Master Sheet'!B12,"") | C11: Area 3 (Saranya R) | D11: =IF('Master Sheet'!C12="Area 3 (Saranya R)",'Master Sheet'!D12,"") | E11: =IF('Master Sheet'!C12="Area 3 (Saranya R)",'Master Sheet'!E12,"") | F11: =IF('Master Sheet'!C12="Area 3 (Saranya R)",'Master Sheet'!F12,"") | G11: =IF('Master Sheet'!C12="Area 3 (Saranya R)",'Master Sheet'!G12,"") | H11: =IF('Master Sheet'!C12="Area 3 (Saranya R)",'Master Sheet'!H12,"") | I11: =IF('Master Sheet'!C12="Area 3 (Saranya R)",'Master Sheet'!I12,"") | J11: =IF('Master Sheet'!C12="Area 3 (Saranya R)",'Master Sheet'!J12,"") | K11: =IF('Master Sheet'!C12="Area 3 (Saranya R)",'Master Sheet'!K12,"") | L11: =IF('Master Sheet'!C12="Area 3 (Saranya R)",'Master Sheet'!L12,"") | M11: =IF('Master Sheet'!C12="Area 3 (Saranya R)",'Master Sheet'!M12,"") | N11: =IF('Master Sheet'!C12="Area 3 (Saranya R)",'Master Sheet'!N12,"") | O11: =IF('Master Sheet'!C12="Area 3 (Saranya R)",'Master Sheet'!O12,"") | P11: =IF('Master Sheet'!C12="Area 3 (Saranya R)",'Master Sheet'!P12,"")
A12: =IF('Master Sheet'!C13="Area 3 (Saranya R)",'Master Sheet'!A13,"") | B12: =IF('Master Sheet'!C13="Area 3 (Saranya R)",'Master Sheet'!B13,"") | C12: Area 3 (Saranya R) | D12: =IF('Master Sheet'!C13="Area 3 (Saranya R)",'Master Sheet'!D13,"") | E12: =IF('Master Sheet'!C13="Area 3 (Saranya R)",'Master Sheet'!E13,"") | F12: =IF('Master Sheet'!C13="Area 3 (Saranya R)",'Master Sheet'!F13,"") | G12: =IF('Master Sheet'!C13="Area 3 (Saranya R)",'Master Sheet'!G13,"") | H12: =IF('Master Sheet'!C13="Area 3 (Saranya R)",'Master Sheet'!H13,"") | I12: =IF('Master Sheet'!C13="Area 3 (Saranya R)",'Master Sheet'!I13,"") | J12: =IF('Master Sheet'!C13="Area 3 (Saranya R)",'Master Sheet'!J13,"") | K12: =IF('Master Sheet'!C13="Area 3 (Saranya R)",'Master Sheet'!K13,"") | L12: =IF('Master Sheet'!C13="Area 3 (Saranya R)",'Master Sheet'!L13,"") | M12: =IF('Master Sheet'!C13="Area 3 (Saranya R)",'Master Sheet'!M13,"") | N12: =IF('Master Sheet'!C13="Area 3 (Saranya R)",'Master Sheet'!N13,"") | O12: =IF('Master Sheet'!C13="Area 3 (Saranya R)",'Master Sheet'!O13,"") | P12: =IF('Master Sheet'!C13="Area 3 (Saranya R)",'Master Sheet'!P13,"")
A13: =IF('Master Sheet'!C14="Area 3 (Saranya R)",'Master Sheet'!A14,"") | B13: =IF('Master Sheet'!C14="Area 3 (Saranya R)",'Master Sheet'!B14,"") | C13: Area 3 (Saranya R) | D13: =IF('Master Sheet'!C14="Area 3 (Saranya R)",'Master Sheet'!D14,"") | E13: =IF('Master Sheet'!C14="Area 3 (Saranya R)",'Master Sheet'!E14,"") | F13: =IF('Master Sheet'!C14="Area 3 (Saranya R)",'Master Sheet'!F14,"") | G13: =IF('Master Sheet'!C14="Area 3 (Saranya R)",'Master Sheet'!G14,"") | H13: =IF('Master Sheet'!C14="Area 3 (Saranya R)",'Master Sheet'!H14,"") | I13: =IF('Master Sheet'!C14="Area 3 (Saranya R)",'Master Sheet'!I14,"") | J13: =IF('Master Sheet'!C14="Area 3 (Saranya R)",'Master Sheet'!J14,"") | K13: =IF('Master Sheet'!C14="Area 3 (Saranya R)",'Master Sheet'!K14,"") | L13: =IF('Master Sheet'!C14="Area 3 (Saranya R)",'Master Sheet'!L14,"") | M13: =IF('Master Sheet'!C14="Area 3 (Saranya R)",'Master Sheet'!M14,"") | N13: =IF('Master Sheet'!C14="Area 3 (Saranya R)",'Master Sheet'!N14,"") | O13: =IF('Master Sheet'!C14="Area 3 (Saranya R)",'Master Sheet'!O14,"") | P13: =IF('Master Sheet'!C14="Area 3 (Saranya R)",'Master Sheet'!P14,"")
... A68: =IF('Master Sheet'!C69="Area 3 (Saranya R)",'Master Sheet'!A69,"") -> P067 | B68: =IF('Master Sheet'!C69="Area 3 (Saranya R)",'Master Sheet'!B69,"") -> Pinky Prasanth | C68: Area 3 (Saranya R) | D68: =IF('Master Sheet'!C69="Area 3 (Saranya R)",'Master Sheet'!D69,"") -> 0 | E68: =IF('Master Sheet'!C69="Area 3 (Saranya R)",'Master Sheet'!E69,"") -> 0 | F68: =IF('Master Sheet'!C69="Area 3 (Saranya R)",'Master Sheet'!F69,"") -> 0 | G68: =IF('Master Sheet'!C69="Area 3 (Saranya R)",'Master Sheet'!G69,"") -> 0 | H68: =IF('Master Sheet'!C69="Area 3 (Saranya R)",'Master Sheet'!H69,"") -> 0 | I68: =IF('Master Sheet'!C69="Area 3 (Saranya R)",'Master Sheet'!I69,"") -> 0 | J68: =IF('Master Sheet'!C69="Area 3 (Saranya R)",'Master Sheet'!J69,"") -> 0 | K68: =IF('Master Sheet'!C69="Area 3 (Saranya R)",'Master Sheet'!K69,"") -> 0 | L68: =IF('Master Sheet'!C69="Area 3 (Saranya R)",'Master Sheet'!L69,"") -> 0 | M68: =IF('Master Sheet'!C69="Area 3 (Saranya R)",'Master Sheet'!M69,"") -> 0 | N68: =IF('Master Sheet'!C69="Area 3 (Saranya R)",'Master Sheet'!N69,"") -> 0 | O68: =IF('Master Sheet'!C69="Area 3 (Saranya R)",'Master Sheet'!O69,"") -> 3500 | P68: =IF('Master Sheet'!C69="Area 3 (Saranya R)",'Master Sheet'!P69,"") -> Pending
A69: =IF('Master Sheet'!C71="Area 3 (Saranya R)",'Master Sheet'!A71,"") | B69: =IF('Master Sheet'!C71="Area 3 (Saranya R)",'Master Sheet'!B71,"") | C69: Area 3 (Saranya R) | D69: =IF('Master Sheet'!C71="Area 3 (Saranya R)",'Master Sheet'!D71,"") | E69: =IF('Master Sheet'!C71="Area 3 (Saranya R)",'Master Sheet'!E71,"") | F69: =IF('Master Sheet'!C71="Area 3 (Saranya R)",'Master Sheet'!F71,"") | G69: =IF('Master Sheet'!C71="Area 3 (Saranya R)",'Master Sheet'!G71,"") | H69: =IF('Master Sheet'!C71="Area 3 (Saranya R)",'Master Sheet'!H71,"") | I69: =IF('Master Sheet'!C71="Area 3 (Saranya R)",'Master Sheet'!I71,"") | J69: =IF('Master Sheet'!C71="Area 3 (Saranya R)",'Master Sheet'!J71,"") | K69: =IF('Master Sheet'!C71="Area 3 (Saranya R)",'Master Sheet'!K71,"") | L69: =IF('Master Sheet'!C71="Area 3 (Saranya R)",'Master Sheet'!L71,"") | M69: =IF('Master Sheet'!C71="Area 3 (Saranya R)",'Master Sheet'!M71,"") | N69: =IF('Master Sheet'!C71="Area 3 (Saranya R)",'Master Sheet'!N71,"") | O69: =IF('Master Sheet'!C71="Area 3 (Saranya R)",'Master Sheet'!O71,"") | P69: =IF('Master Sheet'!C71="Area 3 (Saranya R)",'Master Sheet'!P71,"")
A70: =IF('Master Sheet'!C72="Area 3 (Saranya R)",'Master Sheet'!A72,"") | B70: =IF('Master Sheet'!C72="Area 3 (Saranya R)",'Master Sheet'!B72,"") | C70: Area 3 (Saranya R) | D70: =IF('Master Sheet'!C72="Area 3 (Saranya R)",'Master Sheet'!D72,"") | E70: =IF('Master Sheet'!C72="Area 3 (Saranya R)",'Master Sheet'!E72,"") | F70: =IF('Master Sheet'!C72="Area 3 (Saranya R)",'Master Sheet'!F72,"") | G70: =IF('Master Sheet'!C72="Area 3 (Saranya R)",'Master Sheet'!G72,"") | H70: =IF('Master Sheet'!C72="Area 3 (Saranya R)",'Master Sheet'!H72,"") | I70: =IF('Master Sheet'!C72="Area 3 (Saranya R)",'Master Sheet'!I72,"") | J70: =IF('Master Sheet'!C72="Area 3 (Saranya R)",'Master Sheet'!J72,"") | K70: =IF('Master Sheet'!C72="Area 3 (Saranya R)",'Master Sheet'!K72,"") | L70: =IF('Master Sheet'!C72="Area 3 (Saranya R)",'Master Sheet'!L72,"") | M70: =IF('Master Sheet'!C72="Area 3 (Saranya R)",'Master Sheet'!M72,"") | N70: =IF('Master Sheet'!C72="Area 3 (Saranya R)",'Master Sheet'!N72,"") | O70: =IF('Master Sheet'!C72="Area 3 (Saranya R)",'Master Sheet'!O72,"") | P70: =IF('Master Sheet'!C72="Area 3 (Saranya R)",'Master Sheet'!P72,"")
A71: =IF('Master Sheet'!C73="Area 3 (Saranya R)",'Master Sheet'!A73,"") | B71: =IF('Master Sheet'!C73="Area 3 (Saranya R)",'Master Sheet'!B73,"") | C71: Area 3 (Saranya R) | D71: =IF('Master Sheet'!C73="Area 3 (Saranya R)",'Master Sheet'!D73,"") | E71: =IF('Master Sheet'!C73="Area 3 (Saranya R)",'Master Sheet'!E73,"") | F71: =IF('Master Sheet'!C73="Area 3 (Saranya R)",'Master Sheet'!F73,"") | G71: =IF('Master Sheet'!C73="Area 3 (Saranya R)",'Master Sheet'!G73,"") | H71: =IF('Master Sheet'!C73="Area 3 (Saranya R)",'Master Sheet'!H73,"") | I71: =IF('Master Sheet'!C73="Area 3 (Saranya R)",'Master Sheet'!I73,"") | J71: =IF('Master Sheet'!C73="Area 3 (Saranya R)",'Master Sheet'!J73,"") | K71: =IF('Master Sheet'!C73="Area 3 (Saranya R)",'Master Sheet'!K73,"") | L71: =IF('Master Sheet'!C73="Area 3 (Saranya R)",'Master Sheet'!L73,"") | M71: =IF('Master Sheet'!C73="Area 3 (Saranya R)",'Master Sheet'!M73,"") | N71: =IF('Master Sheet'!C73="Area 3 (Saranya R)",'Master Sheet'!N73,"") | O71: =IF('Master Sheet'!C73="Area 3 (Saranya R)",'Master Sheet'!O73,"") | P71: =IF('Master Sheet'!C73="Area 3 (Saranya R)",'Master Sheet'!P73,"")
A72: =IF('Master Sheet'!C74="Area 3 (Saranya R)",'Master Sheet'!A74,"") | B72: =IF('Master Sheet'!C74="Area 3 (Saranya R)",'Master Sheet'!B74,"") | C72: Area 3 (Saranya R) | D72: =IF('Master Sheet'!C74="Area 3 (Saranya R)",'Master Sheet'!D74,"") | E72: =IF('Master Sheet'!C74="Area 3 (Saranya R)",'Master Sheet'!E74,"") | F72: =IF('Master Sheet'!C74="Area 3 (Saranya R)",'Master Sheet'!F74,"") | G72: =IF('Master Sheet'!C74="Area 3 (Saranya R)",'Master Sheet'!G74,"") | H72: =IF('Master Sheet'!C74="Area 3 (Saranya R)",'Master Sheet'!H74,"") | I72: =IF('Master Sheet'!C74="Area 3 (Saranya R)",'Master Sheet'!I74,"") | J72: =IF('Master Sheet'!C74="Area 3 (Saranya R)",'Master Sheet'!J74,"") | K72: =IF('Master Sheet'!C74="Area 3 (Saranya R)",'Master Sheet'!K74,"") | L72: =IF('Master Sheet'!C74="Area 3 (Saranya R)",'Master Sheet'!L74,"") | M72: =IF('Master Sheet'!C74="Area 3 (Saranya R)",'Master Sheet'!M74,"") | N72: =IF('Master Sheet'!C74="Area 3 (Saranya R)",'Master Sheet'!N74,"") | O72: =IF('Master Sheet'!C74="Area 3 (Saranya R)",'Master Sheet'!O74,"") | P72: =IF('Master Sheet'!C74="Area 3 (Saranya R)",'Master Sheet'!P74,"")
A73: =IF('Master Sheet'!C75="Area 3 (Saranya R)",'Master Sheet'!A75,"") | B73: =IF('Master Sheet'!C75="Area 3 (Saranya R)",'Master Sheet'!B75,"") | C73: Area 3 (Saranya R) | D73: =IF('Master Sheet'!C75="Area 3 (Saranya R)",'Master Sheet'!D75,"") | E73: =IF('Master Sheet'!C75="Area 3 (Saranya R)",'Master Sheet'!E75,"") | F73: =IF('Master Sheet'!C75="Area 3 (Saranya R)",'Master Sheet'!F75,"") | G73: =IF('Master Sheet'!C75="Area 3 (Saranya R)",'Master Sheet'!G75,"") | H73: =IF('Master Sheet'!C75="Area 3 (Saranya R)",'Master Sheet'!H75,"") | I73: =IF('Master Sheet'!C75="Area 3 (Saranya R)",'Master Sheet'!I75,"") | J73: =IF('Master Sheet'!C75="Area 3 (Saranya R)",'Master Sheet'!J75,"") | K73: =IF('Master Sheet'!C75="Area 3 (Saranya R)",'Master Sheet'!K75,"") | L73: =IF('Master Sheet'!C75="Area 3 (Saranya R)",'Master Sheet'!L75,"") | M73: =IF('Master Sheet'!C75="Area 3 (Saranya R)",'Master Sheet'!M75,"") | N73: =IF('Master Sheet'!C75="Area 3 (Saranya R)",'Master Sheet'!N75,"") | O73: =IF('Master Sheet'!C75="Area 3 (Saranya R)",'Master Sheet'!O75,"") | P73: =IF('Master Sheet'!C75="Area 3 (Saranya R)",'Master Sheet'!P75,"")
